<?xml version="1.0"?>
<!--
  Robot: my_robot
  Generated by: LinkForge v1.2.3
  https://github.com/arounamounchili/linkforge
  Date: 2026-02-26 19:32:17
-->
<robot name="my_robot">
  <!-- Links -->
  <link name="base_link">
    <visual>
      <origin xyz="278.701996 256.666199 224.514862" rpy="0 0 0" />
      <geometry>
        <mesh filename="meshes\base_link_visual.stl" />
      </geometry>
    </visual>
    <collision>
      <origin xyz="278.701996 256.666199 224.514862" rpy="0 0 0" />
      <geometry>
        <mesh filename="meshes\base_link_collision.stl" />
      </geometry>
    </collision>
    <inertial>
      <mass value="2" />
      <inertia ixx="5117.153839" ixy="-3.290681" ixz="34.81727" iyy="11038.164675" iyz="0.248639" izz="12024.867466" />
    </inertial>
  </link>
  <link name="BL_femur">
    <visual>
      <origin xyz="204.949707 175.766098 167.814545" rpy="0 0 0" />
      <geometry>
        <mesh filename="meshes\BL_femur_visual.stl" />
      </geometry>
    </visual>
    <collision>
      <origin xyz="204.949707 175.766098 167.814545" rpy="0 0 0" />
      <geometry>
        <mesh filename="meshes\BL_femur_collision.stl" />
      </geometry>
    </collision>
    <inertial>
      <mass value="0.1" />
      <inertia ixx="79.304058" ixy="-0.043833" ixz="-0.91009" iyy="78.913975" iyz="1.54634" izz="4.515861" />
    </inertial>
  </link>
  <link name="BL_shoulder">
    <visual>
      <origin xyz="201.431671 203.720673 225.75412" rpy="0 0 0" />
      <geometry>
        <mesh filename="meshes\BL_shoulder_visual.stl" />
      </geometry>
    </visual>
    <collision>
      <origin xyz="201.431671 203.720673 225.75412" rpy="0 0 0" />
      <geometry>
        <mesh filename="meshes\BL_shoulder_collision.stl" />
      </geometry>
    </collision>
    <inertial>
      <mass value="0.5" />
      <inertia ixx="155.360926" ixy="0.66486" ixz="5.871553" iyy="256.108223" iyz="0.397205" izz="235.537873" />
    </inertial>
  </link>
  <link name="BL_tibia">
    <visual>
      <origin xyz="254.408768 178.159271 120.589371" rpy="0 0 0" />
      <geometry>
        <mesh filename="meshes\BL_tibia_visual.stl" />
      </geometry>
    </visual>
    <collision>
      <origin xyz="254.408768 178.159271 120.589371" rpy="0 0 0" />
      <geometry>
        <mesh filename="meshes\BL_tibia_collision.stl" />
      </geometry>
    </collision>
    <inertial>
      <mass value="0.1" />
      <inertia ixx="7.790682" ixy="0.006487" ixz="0.862537" iyy="92.575166" iyz="-0.001336" izz="94.240245" />
    </inertial>
  </link>
  <link name="BR_femur">
    <visual>
      <origin xyz="204.949707 337.566132 167.814545" rpy="0 0 0" />
      <geometry>
        <mesh filename="meshes\BR_femur_visual.stl" />
      </geometry>
    </visual>
    <collision>
      <origin xyz="204.949707 337.566132 167.814545" rpy="0 0 0" />
      <geometry>
        <mesh filename="meshes\BR_femur_collision.stl" />
      </geometry>
    </collision>
    <inertial>
      <mass value="0.1" />
      <inertia ixx="79.312723" ixy="0.044298" ixz="-0.909595" iyy="78.923787" iyz="-1.546506" izz="4.51524" />
    </inertial>
  </link>
  <link name="BR_shoulder">
    <visual>
      <origin xyz="201.431671 309.611572 225.75412" rpy="0 0 0" />
      <geometry>
        <mesh filename="meshes\BR_shoulder_visual.stl" />
      </geometry>
    </visual>
    <collision>
      <origin xyz="201.431671 309.611572 225.75412" rpy="0 0 0" />
      <geometry>
        <mesh filename="meshes\BR_shoulder_collision.stl" />
      </geometry>
    </collision>
    <inertial>
      <mass value="0.5" />
      <inertia ixx="155.360909" ixy="-0.665147" ixz="5.871217" iyy="256.107577" iyz="-0.396896" izz="235.537382" />
    </inertial>
  </link>
  <link name="BR_tibia">
    <visual>
      <origin xyz="254.429062 334.966125 120.606552" rpy="0 0 0" />
      <geometry>
        <mesh filename="meshes\BR_tibia_visual.stl" />
      </geometry>
    </visual>
    <collision>
      <origin xyz="254.429062 334.966125 120.606552" rpy="0 0 0" />
      <geometry>
        <mesh filename="meshes\BR_tibia_collision.stl" />
      </geometry>
    </collision>
    <inertial>
      <mass value="0.1" />
      <inertia ixx="7.78352" ixy="-0.000287" ixz="0.849992" iyy="92.630165" iyz="-0.000042" izz="94.30061" />
    </inertial>
  </link>
  <link name="FL_femur">
    <visual>
      <origin xyz="367.795715 175.766113 167.814545" rpy="0 0 0" />
      <geometry>
        <mesh filename="meshes\FL_femur_visual.stl" />
      </geometry>
    </visual>
    <collision>
      <origin xyz="367.795715 175.766113 167.814545" rpy="0 0 0" />
      <geometry>
        <mesh filename="meshes\FL_femur_collision.stl" />
      </geometry>
    </collision>
    <inertial>
      <mass value="0.1" />
      <inertia ixx="79.304058" ixy="-0.043834" ixz="-0.910095" iyy="78.913973" iyz="1.546337" izz="4.515861" />
    </inertial>
  </link>
  <link name="FL_shoulder">
    <visual>
      <origin xyz="355.971313 203.720673 225.75412" rpy="0 0 0" />
      <geometry>
        <mesh filename="meshes\FL_shoulder_visual.stl" />
      </geometry>
    </visual>
    <collision>
      <origin xyz="355.971313 203.720673 225.75412" rpy="0 0 0" />
      <geometry>
        <mesh filename="meshes\FL_shoulder_collision.stl" />
      </geometry>
    </collision>
    <inertial>
      <mass value="0.5" />
      <inertia ixx="155.372627" ixy="-0.707372" ixz="-4.306391" iyy="255.936096" iyz="0.636216" izz="235.483446" />
    </inertial>
  </link>
  <link name="FL_tibia">
    <visual>
      <origin xyz="417.254761 178.159271 120.589371" rpy="0 0 0" />
      <geometry>
        <mesh filename="meshes\FL_tibia_visual.stl" />
      </geometry>
    </visual>
    <collision>
      <origin xyz="417.254761 178.159271 120.589371" rpy="0 0 0" />
      <geometry>
        <mesh filename="meshes\FL_tibia_collision.stl" />
      </geometry>
    </collision>
    <inertial>
      <mass value="0.1" />
      <inertia ixx="7.79068" ixy="0.006485" ixz="0.862537" iyy="92.57517" iyz="-0.001336" izz="94.240247" />
    </inertial>
  </link>
  <link name="FR_femur">
    <visual>
      <origin xyz="367.795715 337.566132 167.814545" rpy="0 0 0" />
      <geometry>
        <mesh filename="meshes\FR_femur_visual.stl" />
      </geometry>
    </visual>
    <collision>
      <origin xyz="367.795715 337.566132 167.814545" rpy="0 0 0" />
      <geometry>
        <mesh filename="meshes\FR_femur_collision.stl" />
      </geometry>
    </collision>
    <inertial>
      <mass value="0.1" />
      <inertia ixx="79.312729" ixy="0.044298" ixz="-0.909599" iyy="78.923792" iyz="-1.546506" izz="4.51524" />
    </inertial>
  </link>
  <link name="FR_shoulder">
    <visual>
      <origin xyz="355.971313 309.611572 225.75412" rpy="0 0 0" />
      <geometry>
        <mesh filename="meshes\FR_shoulder_visual.stl" />
      </geometry>
    </visual>
    <collision>
      <origin xyz="355.971313 309.611572 225.75412" rpy="0 0 0" />
      <geometry>
        <mesh filename="meshes\FR_shoulder_collision.stl" />
      </geometry>
    </collision>
    <inertial>
      <mass value="0.5" />
      <inertia ixx="155.367947" ixy="0.753872" ixz="-4.309215" iyy="255.918588" iyz="-0.638185" izz="235.431792" />
    </inertial>
  </link>
  <link name="FR_tibia">
    <visual>
      <origin xyz="417.275024 334.966125 120.606552" rpy="0 0 0" />
      <geometry>
        <mesh filename="meshes\FR_tibia_visual.stl" />
      </geometry>
    </visual>
    <collision>
      <origin xyz="417.275024 334.966125 120.606552" rpy="0 0 0" />
      <geometry>
        <mesh filename="meshes\FR_tibia_collision.stl" />
      </geometry>
    </collision>
    <inertial>
      <mass value="0.1" />
      <inertia ixx="7.783521" ixy="-0.000286" ixz="0.849993" iyy="92.630164" iyz="-0.000041" izz="94.300609" />
    </inertial>
  </link>
  <link name="lidar">
    <visual>
      <origin xyz="331.460419 256.665955 297.15036" rpy="0 0 0" />
      <geometry>
        <mesh filename="meshes\lidar_visual.stl" />
      </geometry>
    </visual>
    <collision>
      <origin xyz="331.460419 256.665955 297.15036" rpy="0 0 0" />
      <geometry>
        <mesh filename="meshes\lidar_collision.stl" />
      </geometry>
    </collision>
    <inertial>
      <mass value="0.1" />
      <inertia ixx="16.901105" ixy="0" ixz="0" iyy="16.901098" iyz="0" izz="26.452203" />
    </inertial>
  </link>
  <link name="imu">
    <visual>
      <origin xyz="274.451477 256.666138 204.879349" rpy="0 0 0" />
      <geometry>
        <mesh filename="meshes\imu_visual.stl" />
      </geometry>
    </visual>
    <collision>
      <origin xyz="274.451477 256.666138 204.879349" rpy="0 0 0" />
      <geometry>
        <mesh filename="meshes\imu_collision.stl" />
      </geometry>
    </collision>
    <inertial>
      <mass value="0.01" />
      <inertia ixx="0.470834" ixy="0" ixz="0" iyy="0.3" iyz="0" izz="0.710834" />
    </inertial>
  </link>
  <!-- Joints -->
  <joint name="FR_tibia_joint" type="revolute">
    <parent link="FR_femur" />
    <child link="FR_tibia" />
    <axis xyz="0 0 1" />
    <limit effort="10" velocity="1" lower="-3.141593" upper="3.141593" />
  </joint>
  <joint name="FR_femur_joint" type="revolute">
    <parent link="FR_shoulder" />
    <child link="FR_femur" />
    <axis xyz="0 0 1" />
    <limit effort="10" velocity="1" lower="-3.141593" upper="3.141593" />
  </joint>
  <joint name="FR_shoulder_joint" type="revolute">
    <parent link="base_link" />
    <child link="FR_shoulder" />
    <axis xyz="0 0 1" />
    <limit effort="10" velocity="1" lower="-3.141593" upper="3.141593" />
  </joint>
  <joint name="BR_tibia_joint" type="revolute">
    <parent link="BR_femur" />
    <child link="BR_tibia" />
    <axis xyz="0 0 1" />
    <limit effort="10" velocity="1" lower="-3.141593" upper="3.141593" />
  </joint>
  <joint name="BR_femur_joint" type="revolute">
    <parent link="BR_shoulder" />
    <child link="BR_femur" />
    <axis xyz="0 0 1" />
    <limit effort="10" velocity="1" lower="-3.141593" upper="3.141593" />
  </joint>
  <joint name="BR_shoulder_joint" type="revolute">
    <parent link="base_link" />
    <child link="BR_shoulder" />
    <axis xyz="0 0 1" />
    <limit effort="10" velocity="1" lower="-3.141593" upper="3.141593" />
  </joint>
  <joint name="FL_tibia_joint" type="revolute">
    <parent link="FL_femur" />
    <child link="FL_tibia" />
    <axis xyz="0 0 1" />
    <limit effort="10" velocity="1" lower="-3.141593" upper="3.141593" />
  </joint>
  <joint name="FL_femur_joint" type="revolute">
    <parent link="FL_shoulder" />
    <child link="FL_femur" />
    <axis xyz="0 0 1" />
    <limit effort="10" velocity="1" lower="-3.141593" upper="3.141593" />
  </joint>
  <joint name="FL_shoulder_joint" type="revolute">
    <parent link="base_link" />
    <child link="FL_shoulder" />
    <axis xyz="0 0 1" />
    <limit effort="10" velocity="1" lower="-3.141593" upper="3.141593" />
  </joint>
  <joint name="BL_tibia_joint" type="revolute">
    <parent link="BL_femur" />
    <child link="BL_tibia" />
    <axis xyz="0 0 1" />
    <limit effort="10" velocity="1" lower="-3.141593" upper="3.141593" />
  </joint>
  <joint name="BL_femur_joint" type="revolute">
    <parent link="BL_shoulder" />
    <child link="BL_femur" />
    <axis xyz="0 0 1" />
    <limit effort="10" velocity="1" lower="-3.141593" upper="3.141593" />
  </joint>
  <joint name="BL_shoulder_joint" type="revolute">
    <parent link="base_link" />
    <child link="BL_shoulder" />
    <axis xyz="0 0 1" />
    <limit effort="10" velocity="1" lower="-3.141593" upper="3.141593" />
  </joint>
  <joint name="lidar_joint" type="fixed">
    <parent link="base_link" />
    <child link="lidar" />
  </joint>
  <joint name="imu_joint" type="fixed">
    <parent link="base_link" />
    <child link="imu" />
  </joint>
  <!-- ROS2 Control -->
  <ros2_control name="GazeboSimSystem" type="system">
    <hardware>
      <plugin>gz_ros2_control/GazeboSimSystem</plugin>
    </hardware>
    <joint name="BL_femur_joint">
      <command_interface name="position" />
      <state_interface name="position" />
      <state_interface name="velocity" />
    </joint>
    <joint name="BL_tibia_joint">
      <command_interface name="position" />
      <state_interface name="position" />
      <state_interface name="velocity" />
    </joint>
    <joint name="BL_shoulder_joint">
      <command_interface name="position" />
      <state_interface name="position" />
      <state_interface name="velocity" />
    </joint>
    <joint name="BR_femur_joint">
      <command_interface name="position" />
      <state_interface name="position" />
      <state_interface name="velocity" />
    </joint>
    <joint name="BR_shoulder_joint">
      <command_interface name="position" />
      <state_interface name="position" />
      <state_interface name="velocity" />
    </joint>
    <joint name="BR_tibia_joint">
      <command_interface name="position" />
      <state_interface name="position" />
      <state_interface name="velocity" />
    </joint>
    <joint name="FL_femur_joint">
      <command_interface name="position" />
      <state_interface name="position" />
      <state_interface name="velocity" />
    </joint>
    <joint name="FL_shoulder_joint">
      <command_interface name="position" />
      <state_interface name="position" />
      <state_interface name="velocity" />
    </joint>
    <joint name="FL_tibia_joint">
      <command_interface name="position" />
      <state_interface name="position" />
      <state_interface name="velocity" />
    </joint>
    <joint name="FR_femur_joint">
      <command_interface name="position" />
      <state_interface name="position" />
      <state_interface name="velocity" />
    </joint>
    <joint name="FR_shoulder_joint">
      <command_interface name="position" />
      <state_interface name="position" />
      <state_interface name="velocity" />
    </joint>
    <joint name="FR_tibia_joint">
      <command_interface name="position" />
      <state_interface name="position" />
      <state_interface name="velocity" />
    </joint>
  </ros2_control>
  <!-- Gazebo -->
  <gazebo>
    <plugin name="gazebo_ros2_control" filename="libgz_ros2_control-system.so">
      <parameters>$(find robot_description)/config/controllers.yaml</parameters>
    </plugin>
  </gazebo>
  <!-- Sensors -->
  <gazebo reference="base_link">
    <sensor name="lidar_link_sensor" type="gpu_lidar">
      <always_on>true</always_on>
      <update_rate>30</update_rate>
      <visualize>false</visualize>
      <ray>
        <scan>
          <horizontal>
            <samples>640</samples>
            <resolution>1</resolution>
            <min_angle>-1.570796</min_angle>
            <max_angle>1.570796</max_angle>
          </horizontal>
        </scan>
        <range>
          <min>0.1</min>
          <max>10</max>
          <resolution>0.01</resolution>
        </range>
      </ray>
    </sensor>
  </gazebo>
  <gazebo reference="base_link">
    <sensor name="imu_link_sensor" type="imu">
      <always_on>true</always_on>
      <update_rate>30</update_rate>
      <visualize>false</visualize>
      <imu />
    </sensor>
  </gazebo>
</robot>